{"timestamp": "2025-05-04T07:47:38.994158", "level": "ERROR", "message": "Failed to load image data: [WinError 3] The system cannot find the path specified: 'data/processed/plantvillage\\\\train'", "logger": "soko_yetu_ai", "module": "image_loader", "function": "get_data_generators", "line": 59}
{"timestamp": "2025-05-04T07:48:17.279646", "level": "ERROR", "message": "Failed to load image data: [WinError 3] The system cannot find the path specified: 'data/processed/plantvillage\\\\train'", "logger": "soko_yetu_ai", "module": "image_loader", "function": "get_data_generators", "line": 59}
{"timestamp": "2025-05-09T16:21:55.821193", "level": "ERROR", "message": "Database URL not configured. Please set the DATABASE_URL environment variable or pass a db_url argument to DataPreprocessor.", "logger": "soko_yetu_ai", "module": "preprocess_data", "function": "__init__", "line": 35}
{"timestamp": "2025-05-09T17:02:51.195930", "level": "INFO", "message": "Successfully loaded environment variables from: C:\\Users\\USER\\Videos\\AgirConnect-AI\\soko-yetu-ai-ml\\.env", "logger": "soko_yetu_ai", "module": "preprocess_data", "function": "<module>", "line": 39}
{"timestamp": "2025-05-09T17:02:51.199507", "level": "INFO", "message": "Attempting to connect to database with URL: sqlite:///sokoyetu_ai.db", "logger": "soko_yetu_ai", "module": "preprocess_data", "function": "__init__", "line": 54}
{"timestamp": "2025-05-09T17:02:52.460242", "level": "INFO", "message": "Price data preprocessed and saved to data/processed/price_data.csv", "logger": "soko_yetu_ai", "module": "preprocess_data", "function": "preprocess_price_data", "line": 108}
{"timestamp": "2025-05-09T17:02:52.743232", "level": "INFO", "message": "Price data saved to database", "logger": "soko_yetu_ai", "module": "preprocess_data", "function": "preprocess_price_data", "line": 112}
{"timestamp": "2025-05-09T17:02:52.973697", "level": "INFO", "message": "Yield data preprocessed and saved to data/processed/yield_data.csv", "logger": "soko_yetu_ai", "module": "preprocess_data", "function": "preprocess_yield_data", "line": 139}
{"timestamp": "2025-05-09T17:02:57.434674", "level": "ERROR", "message": "Yield data preprocessing failed: (sqlite3.OperationalError) duplicate column name: year\n[SQL: \nCREATE TABLE processed_yield_data (\n\t\"Domain Code\" TEXT, \n\t\"Domain\" TEXT, \n\t\"Area Code (M49)\" BIGINT, \n\t\"Area\" TEXT, \n\t\"Element Code\" BIGINT, \n\t\"Element\" TEXT, \n\t\"Item Code (CPC)\" FLOAT, \n\t\"Item\" TEXT, \n\t\"Year Code\" BIGINT, \n\t\"Year\" BIGINT, \n\t\"Unit\" TEXT, \n\t\"Value\" FLOAT, \n\t\"Flag\" TEXT, \n\t\"Flag Description\" TEXT, \n\t\"Note\" FLOAT, \n\tdate DATETIME, \n\tyield_3yr_avg FLOAT, \n\tyield_5yr_avg FLOAT, \n\tmonth INTEGER, \n\tyear INTEGER\n)\n\n]\n(Background on this error at: https://sqlalche.me/e/20/e3q8)", "logger": "soko_yetu_ai", "module": "preprocess_data", "function": "preprocess_yield_data", "line": 148, "exception": "Traceback (most recent call last):\n  File \"C:\\Users\\USER\\AppData\\Local\\Programs\\Python\\Python312\\Lib\\site-packages\\sqlalchemy\\engine\\base.py\", line 1964, in _exec_single_context\n    self.dialect.do_execute(\n  File \"C:\\Users\\USER\\AppData\\Local\\Programs\\Python\\Python312\\Lib\\site-packages\\sqlalchemy\\engine\\default.py\", line 945, in do_execute\n    cursor.execute(statement, parameters)\nsqlite3.OperationalError: duplicate column name: year\n\nThe above exception was the direct cause of the following exception:\n\nTraceback (most recent call last):\n  File \"C:\\Users\\USER\\Videos\\AgirConnect-AI\\soko-yetu-ai-ml\\scripts\\preprocess_data.py\", line 142, in preprocess_yield_data\n    df.to_sql('processed_yield_data', self.engine, if_exists='replace', index=False)\n  File \"C:\\Users\\USER\\AppData\\Local\\Programs\\Python\\Python312\\Lib\\site-packages\\pandas\\util\\_decorators.py\", line 333, in wrapper\n    return func(*args, **kwargs)\n           ^^^^^^^^^^^^^^^^^^^^^\n  File \"C:\\Users\\USER\\AppData\\Local\\Programs\\Python\\Python312\\Lib\\site-packages\\pandas\\core\\generic.py\", line 3087, in to_sql\n    return sql.to_sql(\n           ^^^^^^^^^^^\n  File \"C:\\Users\\USER\\AppData\\Local\\Programs\\Python\\Python312\\Lib\\site-packages\\pandas\\io\\sql.py\", line 842, in to_sql\n    return pandas_sql.to_sql(\n           ^^^^^^^^^^^^^^^^^^\n  File \"C:\\Users\\USER\\AppData\\Local\\Programs\\Python\\Python312\\Lib\\site-packages\\pandas\\io\\sql.py\", line 2008, in to_sql\n    table = self.prep_table(\n            ^^^^^^^^^^^^^^^^\n  File \"C:\\Users\\USER\\AppData\\Local\\Programs\\Python\\Python312\\Lib\\site-packages\\pandas\\io\\sql.py\", line 1912, in prep_table\n    table.create()\n  File \"C:\\Users\\USER\\AppData\\Local\\Programs\\Python\\Python312\\Lib\\site-packages\\pandas\\io\\sql.py\", line 995, in create\n    self._execute_create()\n  File \"C:\\Users\\USER\\AppData\\Local\\Programs\\Python\\Python312\\Lib\\site-packages\\pandas\\io\\sql.py\", line 981, in _execute_create\n    self.table.create(bind=self.pd_sql.con)\n  File \"C:\\Users\\USER\\AppData\\Local\\Programs\\Python\\Python312\\Lib\\site-packages\\sqlalchemy\\sql\\schema.py\", line 1289, in create\n    bind._run_ddl_visitor(ddl.SchemaGenerator, self, checkfirst=checkfirst)\n  File \"C:\\Users\\USER\\AppData\\Local\\Programs\\Python\\Python312\\Lib\\site-packages\\sqlalchemy\\engine\\base.py\", line 2456, in _run_ddl_visitor\n    visitorcallable(self.dialect, self, **kwargs).traverse_single(element)\n  File \"C:\\Users\\USER\\AppData\\Local\\Programs\\Python\\Python312\\Lib\\site-packages\\sqlalchemy\\sql\\visitors.py\", line 664, in traverse_single\n    return meth(obj, **kw)\n           ^^^^^^^^^^^^^^^\n  File \"C:\\Users\\USER\\AppData\\Local\\Programs\\Python\\Python312\\Lib\\site-packages\\sqlalchemy\\sql\\ddl.py\", line 1019, in visit_table\n    )._invoke_with(self.connection)\n      ^^^^^^^^^^^^^^^^^^^^^^^^^^^^^\n  File \"C:\\Users\\USER\\AppData\\Local\\Programs\\Python\\Python312\\Lib\\site-packages\\sqlalchemy\\sql\\ddl.py\", line 321, in _invoke_with\n    return bind.execute(self)\n           ^^^^^^^^^^^^^^^^^^\n  File \"C:\\Users\\USER\\AppData\\Local\\Programs\\Python\\Python312\\Lib\\site-packages\\sqlalchemy\\engine\\base.py\", line 1416, in execute\n    return meth(\n           ^^^^^\n  File \"C:\\Users\\USER\\AppData\\Local\\Programs\\Python\\Python312\\Lib\\site-packages\\sqlalchemy\\sql\\ddl.py\", line 187, in _execute_on_connection\n    return connection._execute_ddl(\n           ^^^^^^^^^^^^^^^^^^^^^^^^\n  File \"C:\\Users\\USER\\AppData\\Local\\Programs\\Python\\Python312\\Lib\\site-packages\\sqlalchemy\\engine\\base.py\", line 1527, in _execute_ddl\n    ret = self._execute_context(\n          ^^^^^^^^^^^^^^^^^^^^^^\n  File \"C:\\Users\\USER\\AppData\\Local\\Programs\\Python\\Python312\\Lib\\site-packages\\sqlalchemy\\engine\\base.py\", line 1843, in _execute_context\n    return self._exec_single_context(\n           ^^^^^^^^^^^^^^^^^^^^^^^^^^\n  File \"C:\\Users\\USER\\AppData\\Local\\Programs\\Python\\Python312\\Lib\\site-packages\\sqlalchemy\\engine\\base.py\", line 1983, in _exec_single_context\n    self._handle_dbapi_exception(\n  File \"C:\\Users\\USER\\AppData\\Local\\Programs\\Python\\Python312\\Lib\\site-packages\\sqlalchemy\\engine\\base.py\", line 2352, in _handle_dbapi_exception\n    raise sqlalchemy_exception.with_traceback(exc_info[2]) from e\n  File \"C:\\Users\\USER\\AppData\\Local\\Programs\\Python\\Python312\\Lib\\site-packages\\sqlalchemy\\engine\\base.py\", line 1964, in _exec_single_context\n    self.dialect.do_execute(\n  File \"C:\\Users\\USER\\AppData\\Local\\Programs\\Python\\Python312\\Lib\\site-packages\\sqlalchemy\\engine\\default.py\", line 945, in do_execute\n    cursor.execute(statement, parameters)\nsqlalchemy.exc.OperationalError: (sqlite3.OperationalError) duplicate column name: year\n[SQL: \nCREATE TABLE processed_yield_data (\n\t\"Domain Code\" TEXT, \n\t\"Domain\" TEXT, \n\t\"Area Code (M49)\" BIGINT, \n\t\"Area\" TEXT, \n\t\"Element Code\" BIGINT, \n\t\"Element\" TEXT, \n\t\"Item Code (CPC)\" FLOAT, \n\t\"Item\" TEXT, \n\t\"Year Code\" BIGINT, \n\t\"Year\" BIGINT, \n\t\"Unit\" TEXT, \n\t\"Value\" FLOAT, \n\t\"Flag\" TEXT, \n\t\"Flag Description\" TEXT, \n\t\"Note\" FLOAT, \n\tdate DATETIME, \n\tyield_3yr_avg FLOAT, \n\tyield_5yr_avg FLOAT, \n\tmonth INTEGER, \n\tyear INTEGER\n)\n\n]\n(Background on this error at: https://sqlalche.me/e/20/e3q8)"}
{"timestamp": "2025-05-09T17:11:29.722468", "level": "INFO", "message": "Successfully loaded environment variables from: C:\\Users\\USER\\Videos\\AgirConnect-AI\\soko-yetu-ai-ml\\.env", "logger": "soko_yetu_ai", "module": "preprocess_data", "function": "<module>", "line": 39}
{"timestamp": "2025-05-09T17:11:29.729746", "level": "INFO", "message": "Attempting to connect to database with URL: sqlite:///sokoyetu_ai.db", "logger": "soko_yetu_ai", "module": "preprocess_data", "function": "__init__", "line": 54}
{"timestamp": "2025-05-09T17:11:29.892576", "level": "INFO", "message": "Price data preprocessed and saved to data/processed/price_data.csv", "logger": "soko_yetu_ai", "module": "preprocess_data", "function": "preprocess_price_data", "line": 108}
{"timestamp": "2025-05-09T17:11:29.987340", "level": "INFO", "message": "Price data saved to database", "logger": "soko_yetu_ai", "module": "preprocess_data", "function": "preprocess_price_data", "line": 112}
{"timestamp": "2025-05-09T17:11:30.051886", "level": "INFO", "message": "Yield data preprocessed and saved to data/processed/yield_data.csv", "logger": "soko_yetu_ai", "module": "preprocess_data", "function": "preprocess_yield_data", "line": 141}
{"timestamp": "2025-05-09T17:11:30.126884", "level": "INFO", "message": "Yield data saved to database", "logger": "soko_yetu_ai", "module": "preprocess_data", "function": "preprocess_yield_data", "line": 145}
{"timestamp": "2025-05-09T17:11:36.824874", "level": "INFO", "message": "Image data preprocessed for crop and saved to data/processed/plantvillage", "logger": "soko_yetu_ai", "module": "preprocess_data", "function": "preprocess_image_data", "line": 178}
{"timestamp": "2025-05-09T17:11:36.866405", "level": "INFO", "message": "crop image metadata saved to database", "logger": "soko_yetu_ai", "module": "preprocess_data", "function": "preprocess_image_data", "line": 187}
{"timestamp": "2025-05-09T17:11:36.891409", "level": "ERROR", "message": "Image data preprocessing failed: [WinError 3] The system cannot find the path specified: 'data/raw/produce_grading'", "logger": "soko_yetu_ai", "module": "preprocess_data", "function": "preprocess_image_data", "line": 190, "exception": "Traceback (most recent call last):\n  File \"C:\\Users\\USER\\Videos\\AgirConnect-AI\\soko-yetu-ai-ml\\scripts\\preprocess_data.py\", line 157, in preprocess_image_data\n    class_dirs = [d for d in os.listdir(raw_dir) if os.path.isdir(os.path.join(raw_dir, d))]\n                             ^^^^^^^^^^^^^^^^^^^\nFileNotFoundError: [WinError 3] The system cannot find the path specified: 'data/raw/produce_grading'"}
{"timestamp": "2025-05-09T18:05:10.306710", "level": "INFO", "message": "Successfully loaded environment variables from: C:\\Users\\USER\\Videos\\AgirConnect-AI\\soko-yetu-ai-ml\\.env", "logger": "soko_yetu_ai", "module": "preprocess_data", "function": "<module>", "line": 39}
{"timestamp": "2025-05-09T18:05:10.312713", "level": "INFO", "message": "Attempting to connect to database with URL: sqlite:///sokoyetu_ai.db", "logger": "soko_yetu_ai", "module": "preprocess_data", "function": "__init__", "line": 54}
{"timestamp": "2025-05-09T18:05:10.810866", "level": "INFO", "message": "Price data preprocessed and saved to data/processed/price_data.csv", "logger": "soko_yetu_ai", "module": "preprocess_data", "function": "preprocess_price_data", "line": 108}
{"timestamp": "2025-05-09T18:05:10.928865", "level": "INFO", "message": "Price data saved to database", "logger": "soko_yetu_ai", "module": "preprocess_data", "function": "preprocess_price_data", "line": 112}
{"timestamp": "2025-05-09T18:05:11.007419", "level": "INFO", "message": "Yield data preprocessed and saved to data/processed/yield_data.csv", "logger": "soko_yetu_ai", "module": "preprocess_data", "function": "preprocess_yield_data", "line": 141}
{"timestamp": "2025-05-09T18:05:11.106520", "level": "INFO", "message": "Yield data saved to database", "logger": "soko_yetu_ai", "module": "preprocess_data", "function": "preprocess_yield_data", "line": 145}
{"timestamp": "2025-05-09T18:05:11.115524", "level": "ERROR", "message": "Image preprocessing failed: 'DataPreprocessor' object has no attribute '_validate_directory'", "logger": "soko_yetu_ai", "module": "preprocess_data", "function": "preprocess_image_data", "line": 216, "exception": "Traceback (most recent call last):\n  File \"C:\\Users\\USER\\Videos\\AgirConnect-AI\\soko-yetu-ai-ml\\scripts\\preprocess_data.py\", line 156, in preprocess_image_data\n    self._validate_directory(raw_dir)\n    ^^^^^^^^^^^^^^^^^^^^^^^^\nAttributeError: 'DataPreprocessor' object has no attribute '_validate_directory'"}
{"timestamp": "2025-05-09T18:07:12.634920", "level": "INFO", "message": "Successfully loaded environment variables from: C:\\Users\\USER\\Videos\\AgirConnect-AI\\soko-yetu-ai-ml\\.env", "logger": "soko_yetu_ai", "module": "preprocess_data", "function": "<module>", "line": 39}
{"timestamp": "2025-05-09T18:07:12.636924", "level": "INFO", "message": "Attempting to connect to database with URL: sqlite:///sokoyetu_ai.db", "logger": "soko_yetu_ai", "module": "preprocess_data", "function": "__init__", "line": 54}
{"timestamp": "2025-05-09T18:07:12.873569", "level": "INFO", "message": "Price data preprocessed and saved to data/processed/price_data.csv", "logger": "soko_yetu_ai", "module": "preprocess_data", "function": "preprocess_price_data", "line": 108}
{"timestamp": "2025-05-09T18:07:13.153530", "level": "INFO", "message": "Price data saved to database", "logger": "soko_yetu_ai", "module": "preprocess_data", "function": "preprocess_price_data", "line": 112}
{"timestamp": "2025-05-09T18:07:13.274783", "level": "INFO", "message": "Yield data preprocessed and saved to data/processed/yield_data.csv", "logger": "soko_yetu_ai", "module": "preprocess_data", "function": "preprocess_yield_data", "line": 141}
{"timestamp": "2025-05-09T18:07:13.424557", "level": "INFO", "message": "Yield data saved to database", "logger": "soko_yetu_ai", "module": "preprocess_data", "function": "preprocess_yield_data", "line": 145}
{"timestamp": "2025-05-09T18:07:18.931152", "level": "INFO", "message": "Image data preprocessed for crop and saved to data/processed/plantvillage", "logger": "soko_yetu_ai", "module": "preprocess_data", "function": "preprocess_image_data", "line": 178}
{"timestamp": "2025-05-09T18:07:19.002628", "level": "INFO", "message": "crop image metadata saved to database", "logger": "soko_yetu_ai", "module": "preprocess_data", "function": "preprocess_image_data", "line": 187}
{"timestamp": "2025-05-09T18:07:19.021628", "level": "ERROR", "message": "Image data preprocessing failed: [WinError 3] The system cannot find the path specified: 'data/raw/produce_grading'", "logger": "soko_yetu_ai", "module": "preprocess_data", "function": "preprocess_image_data", "line": 190, "exception": "Traceback (most recent call last):\n  File \"C:\\Users\\USER\\Videos\\AgirConnect-AI\\soko-yetu-ai-ml\\scripts\\preprocess_data.py\", line 157, in preprocess_image_data\n    class_dirs = [d for d in os.listdir(raw_dir) if os.path.isdir(os.path.join(raw_dir, d))]\n                             ^^^^^^^^^^^^^^^^^^^\nFileNotFoundError: [WinError 3] The system cannot find the path specified: 'data/raw/produce_grading'"}
{"timestamp": "2025-05-09T20:18:07.291157", "level": "INFO", "message": "Loaded 33027 training images", "logger": "soko_yetu_ai", "module": "image_loader", "function": "get_data_generators", "line": 52}
{"timestamp": "2025-05-09T20:18:07.292162", "level": "INFO", "message": "Loaded 8249 validation images", "logger": "soko_yetu_ai", "module": "image_loader", "function": "get_data_generators", "line": 53}
{"timestamp": "2025-05-09T20:18:07.293160", "level": "INFO", "message": "Loaded 41276 test images", "logger": "soko_yetu_ai", "module": "image_loader", "function": "get_data_generators", "line": 54}
{"timestamp": "2025-05-09T20:21:17.933871", "level": "INFO", "message": "Loaded 33027 training images", "logger": "soko_yetu_ai", "module": "image_loader", "function": "get_data_generators", "line": 52}
{"timestamp": "2025-05-09T20:21:17.934870", "level": "INFO", "message": "Loaded 8249 validation images", "logger": "soko_yetu_ai", "module": "image_loader", "function": "get_data_generators", "line": 53}
{"timestamp": "2025-05-09T20:21:17.935872", "level": "INFO", "message": "Loaded 41276 test images", "logger": "soko_yetu_ai", "module": "image_loader", "function": "get_data_generators", "line": 54}
{"timestamp": "2025-05-09T20:21:22.139278", "level": "WARNING", "message": "Retrying (Retry(total=6, connect=6, read=7, redirect=7, status=7)) after connection broken by 'NewConnectionError('<urllib3.connection.HTTPConnection object at 0x0000021DCDDD00B0>: Failed to establish a new connection: [WinError 10061] No connection could be made because the target machine actively refused it')': /api/2.0/mlflow/experiments/create", "logger": "urllib3.connectionpool", "module": "connectionpool", "function": "urlopen", "line": 868}
{"timestamp": "2025-05-09T20:21:30.939122", "level": "WARNING", "message": "Retrying (Retry(total=5, connect=5, read=7, redirect=7, status=7)) after connection broken by 'NewConnectionError('<urllib3.connection.HTTPConnection object at 0x0000021DCDDD38F0>: Failed to establish a new connection: [WinError 10061] No connection could be made because the target machine actively refused it')': /api/2.0/mlflow/experiments/create", "logger": "urllib3.connectionpool", "module": "connectionpool", "function": "urlopen", "line": 868}
{"timestamp": "2025-05-09T20:21:43.388061", "level": "WARNING", "message": "Retrying (Retry(total=4, connect=4, read=7, redirect=7, status=7)) after connection broken by 'NewConnectionError('<urllib3.connection.HTTPConnection object at 0x0000021DCDDD39E0>: Failed to establish a new connection: [WinError 10061] No connection could be made because the target machine actively refused it')': /api/2.0/mlflow/experiments/create", "logger": "urllib3.connectionpool", "module": "connectionpool", "function": "urlopen", "line": 868}
{"timestamp": "2025-05-09T20:22:03.809063", "level": "WARNING", "message": "Retrying (Retry(total=3, connect=3, read=7, redirect=7, status=7)) after connection broken by 'NewConnectionError('<urllib3.connection.HTTPConnection object at 0x0000021DCDDD3920>: Failed to establish a new connection: [WinError 10061] No connection could be made because the target machine actively refused it')': /api/2.0/mlflow/experiments/create", "logger": "urllib3.connectionpool", "module": "connectionpool", "function": "urlopen", "line": 868}
{"timestamp": "2025-05-09T20:22:40.353641", "level": "WARNING", "message": "Retrying (Retry(total=2, connect=2, read=7, redirect=7, status=7)) after connection broken by 'NewConnectionError('<urllib3.connection.HTTPConnection object at 0x0000021DCDDD3410>: Failed to establish a new connection: [WinError 10061] No connection could be made because the target machine actively refused it')': /api/2.0/mlflow/experiments/create", "logger": "urllib3.connectionpool", "module": "connectionpool", "function": "urlopen", "line": 868}
{"timestamp": "2025-05-09T20:23:49.001914", "level": "WARNING", "message": "Retrying (Retry(total=1, connect=1, read=7, redirect=7, status=7)) after connection broken by 'NewConnectionError('<urllib3.connection.HTTPConnection object at 0x0000021DCDDD36B0>: Failed to establish a new connection: [WinError 10061] No connection could be made because the target machine actively refused it')': /api/2.0/mlflow/experiments/create", "logger": "urllib3.connectionpool", "module": "connectionpool", "function": "urlopen", "line": 868}
{"timestamp": "2025-05-09T20:25:53.154841", "level": "WARNING", "message": "Retrying (Retry(total=0, connect=0, read=7, redirect=7, status=7)) after connection broken by 'NewConnectionError('<urllib3.connection.HTTPConnection object at 0x0000021DCDDD3740>: Failed to establish a new connection: [WinError 10061] No connection could be made because the target machine actively refused it')': /api/2.0/mlflow/experiments/create", "logger": "urllib3.connectionpool", "module": "connectionpool", "function": "urlopen", "line": 868}
{"timestamp": "2025-05-09T20:26:01.486109", "level": "WARNING", "message": "Retrying (Retry(total=6, connect=6, read=7, redirect=7, status=7)) after connection broken by 'NewConnectionError('<urllib3.connection.HTTPConnection object at 0x0000021DCDD964E0>: Failed to establish a new connection: [WinError 10061] No connection could be made because the target machine actively refused it')': /api/2.0/mlflow/experiments/get-by-name?experiment_name=soko_yetu_ai", "logger": "urllib3.connectionpool", "module": "connectionpool", "function": "urlopen", "line": 868}
{"timestamp": "2025-05-09T20:26:10.008861", "level": "WARNING", "message": "Retrying (Retry(total=5, connect=5, read=7, redirect=7, status=7)) after connection broken by 'NewConnectionError('<urllib3.connection.HTTPConnection object at 0x0000021DCDD96750>: Failed to establish a new connection: [WinError 10061] No connection could be made because the target machine actively refused it')': /api/2.0/mlflow/experiments/get-by-name?experiment_name=soko_yetu_ai", "logger": "urllib3.connectionpool", "module": "connectionpool", "function": "urlopen", "line": 868}
{"timestamp": "2025-05-09T20:26:23.014137", "level": "WARNING", "message": "Retrying (Retry(total=4, connect=4, read=7, redirect=7, status=7)) after connection broken by 'NewConnectionError('<urllib3.connection.HTTPConnection object at 0x0000021DCDD968D0>: Failed to establish a new connection: [WinError 10061] No connection could be made because the target machine actively refused it')': /api/2.0/mlflow/experiments/get-by-name?experiment_name=soko_yetu_ai", "logger": "urllib3.connectionpool", "module": "connectionpool", "function": "urlopen", "line": 868}
{"timestamp": "2025-05-09T20:26:43.328306", "level": "WARNING", "message": "Retrying (Retry(total=3, connect=3, read=7, redirect=7, status=7)) after connection broken by 'NewConnectionError('<urllib3.connection.HTTPConnection object at 0x0000021DCDD96AB0>: Failed to establish a new connection: [WinError 10061] No connection could be made because the target machine actively refused it')': /api/2.0/mlflow/experiments/get-by-name?experiment_name=soko_yetu_ai", "logger": "urllib3.connectionpool", "module": "connectionpool", "function": "urlopen", "line": 868}
{"timestamp": "2025-05-09T20:27:19.779947", "level": "WARNING", "message": "Retrying (Retry(total=2, connect=2, read=7, redirect=7, status=7)) after connection broken by 'NewConnectionError('<urllib3.connection.HTTPConnection object at 0x0000021DCDD96CF0>: Failed to establish a new connection: [WinError 10061] No connection could be made because the target machine actively refused it')': /api/2.0/mlflow/experiments/get-by-name?experiment_name=soko_yetu_ai", "logger": "urllib3.connectionpool", "module": "connectionpool", "function": "urlopen", "line": 868}
{"timestamp": "2025-05-09T20:28:28.807485", "level": "WARNING", "message": "Retrying (Retry(total=1, connect=1, read=7, redirect=7, status=7)) after connection broken by 'NewConnectionError('<urllib3.connection.HTTPConnection object at 0x0000021DCDD96EA0>: Failed to establish a new connection: [WinError 10061] No connection could be made because the target machine actively refused it')': /api/2.0/mlflow/experiments/get-by-name?experiment_name=soko_yetu_ai", "logger": "urllib3.connectionpool", "module": "connectionpool", "function": "urlopen", "line": 868}
{"timestamp": "2025-05-09T20:30:32.853235", "level": "WARNING", "message": "Retrying (Retry(total=0, connect=0, read=7, redirect=7, status=7)) after connection broken by 'NewConnectionError('<urllib3.connection.HTTPConnection object at 0x0000021DCDB4FAA0>: Failed to establish a new connection: [WinError 10061] No connection could be made because the target machine actively refused it')': /api/2.0/mlflow/experiments/get-by-name?experiment_name=soko_yetu_ai", "logger": "urllib3.connectionpool", "module": "connectionpool", "function": "urlopen", "line": 868}
{"timestamp": "2025-05-09T20:36:40.725863", "level": "INFO", "message": "Loaded 33027 training images", "logger": "soko_yetu_ai", "module": "image_loader", "function": "get_data_generators", "line": 52}
{"timestamp": "2025-05-09T20:36:40.727875", "level": "INFO", "message": "Loaded 8249 validation images", "logger": "soko_yetu_ai", "module": "image_loader", "function": "get_data_generators", "line": 53}
{"timestamp": "2025-05-09T20:36:40.729449", "level": "INFO", "message": "Loaded 41276 test images", "logger": "soko_yetu_ai", "module": "image_loader", "function": "get_data_generators", "line": 54}
{"timestamp": "2025-05-09T20:36:44.952086", "level": "WARNING", "message": "Retrying (Retry(total=6, connect=6, read=7, redirect=7, status=7)) after connection broken by 'NewConnectionError('<urllib3.connection.HTTPConnection object at 0x000002B084FF7A40>: Failed to establish a new connection: [WinError 10061] No connection could be made because the target machine actively refused it')': /api/2.0/mlflow/experiments/create", "logger": "urllib3.connectionpool", "module": "connectionpool", "function": "urlopen", "line": 868}
{"timestamp": "2025-05-09T20:36:53.937004", "level": "WARNING", "message": "Retrying (Retry(total=5, connect=5, read=7, redirect=7, status=7)) after connection broken by 'NewConnectionError('<urllib3.connection.HTTPConnection object at 0x000002B085562F90>: Failed to establish a new connection: [WinError 10061] No connection could be made because the target machine actively refused it')': /api/2.0/mlflow/experiments/create", "logger": "urllib3.connectionpool", "module": "connectionpool", "function": "urlopen", "line": 868}
{"timestamp": "2025-05-09T20:37:06.908183", "level": "WARNING", "message": "Retrying (Retry(total=4, connect=4, read=7, redirect=7, status=7)) after connection broken by 'NewConnectionError('<urllib3.connection.HTTPConnection object at 0x000002B085563E30>: Failed to establish a new connection: [WinError 10061] No connection could be made because the target machine actively refused it')': /api/2.0/mlflow/experiments/create", "logger": "urllib3.connectionpool", "module": "connectionpool", "function": "urlopen", "line": 868}
{"timestamp": "2025-05-09T20:37:27.722215", "level": "WARNING", "message": "Retrying (Retry(total=3, connect=3, read=7, redirect=7, status=7)) after connection broken by 'NewConnectionError('<urllib3.connection.HTTPConnection object at 0x000002B085563EC0>: Failed to establish a new connection: [WinError 10061] No connection could be made because the target machine actively refused it')': /api/2.0/mlflow/experiments/create", "logger": "urllib3.connectionpool", "module": "connectionpool", "function": "urlopen", "line": 868}
{"timestamp": "2025-05-09T20:38:04.401714", "level": "WARNING", "message": "Retrying (Retry(total=2, connect=2, read=7, redirect=7, status=7)) after connection broken by 'NewConnectionError('<urllib3.connection.HTTPConnection object at 0x000002B085563080>: Failed to establish a new connection: [WinError 10061] No connection could be made because the target machine actively refused it')': /api/2.0/mlflow/experiments/create", "logger": "urllib3.connectionpool", "module": "connectionpool", "function": "urlopen", "line": 868}
{"timestamp": "2025-05-09T20:39:12.728335", "level": "WARNING", "message": "Retrying (Retry(total=1, connect=1, read=7, redirect=7, status=7)) after connection broken by 'NewConnectionError('<urllib3.connection.HTTPConnection object at 0x000002B085562A80>: Failed to establish a new connection: [WinError 10061] No connection could be made because the target machine actively refused it')': /api/2.0/mlflow/experiments/create", "logger": "urllib3.connectionpool", "module": "connectionpool", "function": "urlopen", "line": 868}
{"timestamp": "2025-05-09T20:41:16.787834", "level": "WARNING", "message": "Retrying (Retry(total=0, connect=0, read=7, redirect=7, status=7)) after connection broken by 'NewConnectionError('<urllib3.connection.HTTPConnection object at 0x000002B085563FB0>: Failed to establish a new connection: [WinError 10061] No connection could be made because the target machine actively refused it')': /api/2.0/mlflow/experiments/create", "logger": "urllib3.connectionpool", "module": "connectionpool", "function": "urlopen", "line": 868}
{"timestamp": "2025-05-09T20:41:24.906749", "level": "WARNING", "message": "Retrying (Retry(total=6, connect=6, read=7, redirect=7, status=7)) after connection broken by 'NewConnectionError('<urllib3.connection.HTTPConnection object at 0x000002B085526000>: Failed to establish a new connection: [WinError 10061] No connection could be made because the target machine actively refused it')': /api/2.0/mlflow/experiments/get-by-name?experiment_name=soko_yetu_ai", "logger": "urllib3.connectionpool", "module": "connectionpool", "function": "urlopen", "line": 868}
{"timestamp": "2025-05-09T20:41:33.302630", "level": "WARNING", "message": "Retrying (Retry(total=5, connect=5, read=7, redirect=7, status=7)) after connection broken by 'NewConnectionError('<urllib3.connection.HTTPConnection object at 0x000002B085526150>: Failed to establish a new connection: [WinError 10061] No connection could be made because the target machine actively refused it')': /api/2.0/mlflow/experiments/get-by-name?experiment_name=soko_yetu_ai", "logger": "urllib3.connectionpool", "module": "connectionpool", "function": "urlopen", "line": 868}
{"timestamp": "2025-05-09T20:41:46.217585", "level": "WARNING", "message": "Retrying (Retry(total=4, connect=4, read=7, redirect=7, status=7)) after connection broken by 'NewConnectionError('<urllib3.connection.HTTPConnection object at 0x000002B085526420>: Failed to establish a new connection: [WinError 10061] No connection could be made because the target machine actively refused it')': /api/2.0/mlflow/experiments/get-by-name?experiment_name=soko_yetu_ai", "logger": "urllib3.connectionpool", "module": "connectionpool", "function": "urlopen", "line": 868}
{"timestamp": "2025-05-09T20:42:06.437488", "level": "WARNING", "message": "Retrying (Retry(total=3, connect=3, read=7, redirect=7, status=7)) after connection broken by 'NewConnectionError('<urllib3.connection.HTTPConnection object at 0x000002B085526570>: Failed to establish a new connection: [WinError 10061] No connection could be made because the target machine actively refused it')': /api/2.0/mlflow/experiments/get-by-name?experiment_name=soko_yetu_ai", "logger": "urllib3.connectionpool", "module": "connectionpool", "function": "urlopen", "line": 868}
{"timestamp": "2025-05-09T20:42:42.933876", "level": "WARNING", "message": "Retrying (Retry(total=2, connect=2, read=7, redirect=7, status=7)) after connection broken by 'NewConnectionError('<urllib3.connection.HTTPConnection object at 0x000002B085526780>: Failed to establish a new connection: [WinError 10061] No connection could be made because the target machine actively refused it')': /api/2.0/mlflow/experiments/get-by-name?experiment_name=soko_yetu_ai", "logger": "urllib3.connectionpool", "module": "connectionpool", "function": "urlopen", "line": 868}
{"timestamp": "2025-05-09T20:43:51.586261", "level": "WARNING", "message": "Retrying (Retry(total=1, connect=1, read=7, redirect=7, status=7)) after connection broken by 'NewConnectionError('<urllib3.connection.HTTPConnection object at 0x000002B0855269C0>: Failed to establish a new connection: [WinError 10061] No connection could be made because the target machine actively refused it')': /api/2.0/mlflow/experiments/get-by-name?experiment_name=soko_yetu_ai", "logger": "urllib3.connectionpool", "module": "connectionpool", "function": "urlopen", "line": 868}
{"timestamp": "2025-05-09T20:45:55.645138", "level": "WARNING", "message": "Retrying (Retry(total=0, connect=0, read=7, redirect=7, status=7)) after connection broken by 'NewConnectionError('<urllib3.connection.HTTPConnection object at 0x000002B0854E0EC0>: Failed to establish a new connection: [WinError 10061] No connection could be made because the target machine actively refused it')': /api/2.0/mlflow/experiments/get-by-name?experiment_name=soko_yetu_ai", "logger": "urllib3.connectionpool", "module": "connectionpool", "function": "urlopen", "line": 868}
{"timestamp": "2025-05-10T06:19:15.441439", "level": "INFO", "message": "Loaded 33027 training images", "logger": "soko_yetu_ai", "module": "image_loader", "function": "get_data_generators", "line": 52}
{"timestamp": "2025-05-10T06:19:15.442439", "level": "INFO", "message": "Loaded 8249 validation images", "logger": "soko_yetu_ai", "module": "image_loader", "function": "get_data_generators", "line": 53}
{"timestamp": "2025-05-10T06:19:15.443441", "level": "INFO", "message": "Loaded 41276 test images", "logger": "soko_yetu_ai", "module": "image_loader", "function": "get_data_generators", "line": 54}
{"timestamp": "2025-05-10T06:19:19.639785", "level": "WARNING", "message": "Retrying (Retry(total=6, connect=6, read=7, redirect=7, status=7)) after connection broken by 'NewConnectionError('<urllib3.connection.HTTPConnection object at 0x00000179CBC37BF0>: Failed to establish a new connection: [WinError 10061] No connection could be made because the target machine actively refused it')': /api/2.0/mlflow/experiments/create", "logger": "urllib3.connectionpool", "module": "connectionpool", "function": "urlopen", "line": 868}
{"timestamp": "2025-05-10T06:19:27.876568", "level": "WARNING", "message": "Retrying (Retry(total=5, connect=5, read=7, redirect=7, status=7)) after connection broken by 'NewConnectionError('<urllib3.connection.HTTPConnection object at 0x00000179CC225010>: Failed to establish a new connection: [WinError 10061] No connection could be made because the target machine actively refused it')': /api/2.0/mlflow/experiments/create", "logger": "urllib3.connectionpool", "module": "connectionpool", "function": "urlopen", "line": 868}
{"timestamp": "2025-05-10T06:19:40.287667", "level": "WARNING", "message": "Retrying (Retry(total=4, connect=4, read=7, redirect=7, status=7)) after connection broken by 'NewConnectionError('<urllib3.connection.HTTPConnection object at 0x00000179CC225100>: Failed to establish a new connection: [WinError 10061] No connection could be made because the target machine actively refused it')': /api/2.0/mlflow/experiments/create", "logger": "urllib3.connectionpool", "module": "connectionpool", "function": "urlopen", "line": 868}
{"timestamp": "2025-05-10T06:20:00.569964", "level": "WARNING", "message": "Retrying (Retry(total=3, connect=3, read=7, redirect=7, status=7)) after connection broken by 'NewConnectionError('<urllib3.connection.HTTPConnection object at 0x00000179CC225280>: Failed to establish a new connection: [WinError 10061] No connection could be made because the target machine actively refused it')': /api/2.0/mlflow/experiments/create", "logger": "urllib3.connectionpool", "module": "connectionpool", "function": "urlopen", "line": 868}
{"timestamp": "2025-05-10T06:20:37.310044", "level": "WARNING", "message": "Retrying (Retry(total=2, connect=2, read=7, redirect=7, status=7)) after connection broken by 'NewConnectionError('<urllib3.connection.HTTPConnection object at 0x00000179CC225400>: Failed to establish a new connection: [WinError 10061] No connection could be made because the target machine actively refused it')': /api/2.0/mlflow/experiments/create", "logger": "urllib3.connectionpool", "module": "connectionpool", "function": "urlopen", "line": 868}
{"timestamp": "2025-05-10T06:21:45.607692", "level": "WARNING", "message": "Retrying (Retry(total=1, connect=1, read=7, redirect=7, status=7)) after connection broken by 'NewConnectionError('<urllib3.connection.HTTPConnection object at 0x00000179CC225640>: Failed to establish a new connection: [WinError 10061] No connection could be made because the target machine actively refused it')': /api/2.0/mlflow/experiments/create", "logger": "urllib3.connectionpool", "module": "connectionpool", "function": "urlopen", "line": 868}
{"timestamp": "2025-05-10T06:23:49.658362", "level": "WARNING", "message": "Retrying (Retry(total=0, connect=0, read=7, redirect=7, status=7)) after connection broken by 'NewConnectionError('<urllib3.connection.HTTPConnection object at 0x00000179CC225730>: Failed to establish a new connection: [WinError 10061] No connection could be made because the target machine actively refused it')': /api/2.0/mlflow/experiments/create", "logger": "urllib3.connectionpool", "module": "connectionpool", "function": "urlopen", "line": 868}
{"timestamp": "2025-05-10T06:23:57.807712", "level": "WARNING", "message": "Retrying (Retry(total=6, connect=6, read=7, redirect=7, status=7)) after connection broken by 'NewConnectionError('<urllib3.connection.HTTPConnection object at 0x00000179CC226960>: Failed to establish a new connection: [WinError 10061] No connection could be made because the target machine actively refused it')': /api/2.0/mlflow/experiments/get-by-name?experiment_name=soko_yetu_ai", "logger": "urllib3.connectionpool", "module": "connectionpool", "function": "urlopen", "line": 868}
{"timestamp": "2025-05-10T06:24:06.573846", "level": "WARNING", "message": "Retrying (Retry(total=5, connect=5, read=7, redirect=7, status=7)) after connection broken by 'NewConnectionError('<urllib3.connection.HTTPConnection object at 0x00000179CC226BD0>: Failed to establish a new connection: [WinError 10061] No connection could be made because the target machine actively refused it')': /api/2.0/mlflow/experiments/get-by-name?experiment_name=soko_yetu_ai", "logger": "urllib3.connectionpool", "module": "connectionpool", "function": "urlopen", "line": 868}
{"timestamp": "2025-05-10T06:24:19.362088", "level": "WARNING", "message": "Retrying (Retry(total=4, connect=4, read=7, redirect=7, status=7)) after connection broken by 'NewConnectionError('<urllib3.connection.HTTPConnection object at 0x00000179CC226DE0>: Failed to establish a new connection: [WinError 10061] No connection could be made because the target machine actively refused it')': /api/2.0/mlflow/experiments/get-by-name?experiment_name=soko_yetu_ai", "logger": "urllib3.connectionpool", "module": "connectionpool", "function": "urlopen", "line": 868}
{"timestamp": "2025-05-10T06:24:39.776341", "level": "WARNING", "message": "Retrying (Retry(total=3, connect=3, read=7, redirect=7, status=7)) after connection broken by 'NewConnectionError('<urllib3.connection.HTTPConnection object at 0x00000179CC226FC0>: Failed to establish a new connection: [WinError 10061] No connection could be made because the target machine actively refused it')': /api/2.0/mlflow/experiments/get-by-name?experiment_name=soko_yetu_ai", "logger": "urllib3.connectionpool", "module": "connectionpool", "function": "urlopen", "line": 868}
{"timestamp": "2025-05-10T06:25:15.879131", "level": "WARNING", "message": "Retrying (Retry(total=2, connect=2, read=7, redirect=7, status=7)) after connection broken by 'NewConnectionError('<urllib3.connection.HTTPConnection object at 0x00000179CC2271A0>: Failed to establish a new connection: [WinError 10061] No connection could be made because the target machine actively refused it')': /api/2.0/mlflow/experiments/get-by-name?experiment_name=soko_yetu_ai", "logger": "urllib3.connectionpool", "module": "connectionpool", "function": "urlopen", "line": 868}
{"timestamp": "2025-05-10T06:26:24.370855", "level": "WARNING", "message": "Retrying (Retry(total=1, connect=1, read=7, redirect=7, status=7)) after connection broken by 'NewConnectionError('<urllib3.connection.HTTPConnection object at 0x00000179CC227380>: Failed to establish a new connection: [WinError 10061] No connection could be made because the target machine actively refused it')': /api/2.0/mlflow/experiments/get-by-name?experiment_name=soko_yetu_ai", "logger": "urllib3.connectionpool", "module": "connectionpool", "function": "urlopen", "line": 868}
{"timestamp": "2025-05-10T06:28:28.436095", "level": "WARNING", "message": "Retrying (Retry(total=0, connect=0, read=7, redirect=7, status=7)) after connection broken by 'NewConnectionError('<urllib3.connection.HTTPConnection object at 0x00000179CBF9A0F0>: Failed to establish a new connection: [WinError 10061] No connection could be made because the target machine actively refused it')': /api/2.0/mlflow/experiments/get-by-name?experiment_name=soko_yetu_ai", "logger": "urllib3.connectionpool", "module": "connectionpool", "function": "urlopen", "line": 868}
{"timestamp": "2025-05-12T11:13:07.496255", "level": "INFO", "message": "Loaded 0 training images", "logger": "soko_yetu_ai", "module": "image_loader", "function": "get_data_generators", "line": 52}
{"timestamp": "2025-05-12T11:13:07.499270", "level": "INFO", "message": "Loaded 0 validation images", "logger": "soko_yetu_ai", "module": "image_loader", "function": "get_data_generators", "line": 53}
{"timestamp": "2025-05-12T11:13:07.500258", "level": "INFO", "message": "Loaded 0 test images", "logger": "soko_yetu_ai", "module": "image_loader", "function": "get_data_generators", "line": 54}
{"timestamp": "2025-05-12T11:25:48.216756", "level": "INFO", "message": "Loaded 0 training images", "logger": "soko_yetu_ai", "module": "image_loader", "function": "get_data_generators", "line": 52}
{"timestamp": "2025-05-12T11:25:48.218758", "level": "INFO", "message": "Loaded 0 validation images", "logger": "soko_yetu_ai", "module": "image_loader", "function": "get_data_generators", "line": 53}
{"timestamp": "2025-05-12T11:25:48.220765", "level": "INFO", "message": "Loaded 0 test images", "logger": "soko_yetu_ai", "module": "image_loader", "function": "get_data_generators", "line": 54}
{"timestamp": "2025-05-12T11:38:49.879213", "level": "INFO", "message": "Loaded 0 training images", "logger": "soko_yetu_ai", "module": "image_loader", "function": "get_data_generators", "line": 52}
{"timestamp": "2025-05-12T11:38:49.881216", "level": "INFO", "message": "Loaded 0 validation images", "logger": "soko_yetu_ai", "module": "image_loader", "function": "get_data_generators", "line": 53}
{"timestamp": "2025-05-12T11:38:49.882213", "level": "INFO", "message": "Loaded 0 test images", "logger": "soko_yetu_ai", "module": "image_loader", "function": "get_data_generators", "line": 54}
{"timestamp": "2025-05-12T11:41:46.878499", "level": "INFO", "message": "Loaded 0 training images", "logger": "soko_yetu_ai", "module": "image_loader", "function": "get_data_generators", "line": 52}
{"timestamp": "2025-05-12T11:41:46.879494", "level": "INFO", "message": "Loaded 0 validation images", "logger": "soko_yetu_ai", "module": "image_loader", "function": "get_data_generators", "line": 53}
{"timestamp": "2025-05-12T11:41:46.880497", "level": "INFO", "message": "Loaded 0 test images", "logger": "soko_yetu_ai", "module": "image_loader", "function": "get_data_generators", "line": 54}
{"timestamp": "2025-05-12T12:58:15.984139", "level": "INFO", "message": "Loaded 0 training images", "logger": "soko_yetu_ai", "module": "image_loader", "function": "get_data_generators", "line": 52}
{"timestamp": "2025-05-12T12:58:15.986161", "level": "INFO", "message": "Loaded 0 validation images", "logger": "soko_yetu_ai", "module": "image_loader", "function": "get_data_generators", "line": 53}
{"timestamp": "2025-05-12T12:58:15.988543", "level": "INFO", "message": "Loaded 0 test images", "logger": "soko_yetu_ai", "module": "image_loader", "function": "get_data_generators", "line": 54}
{"timestamp": "2025-05-12T12:58:48.842168", "level": "INFO", "message": "Loaded 0 training images", "logger": "soko_yetu_ai", "module": "image_loader", "function": "get_data_generators", "line": 52}
{"timestamp": "2025-05-12T12:58:48.843173", "level": "INFO", "message": "Loaded 0 validation images", "logger": "soko_yetu_ai", "module": "image_loader", "function": "get_data_generators", "line": 53}
{"timestamp": "2025-05-12T12:58:48.844170", "level": "INFO", "message": "Loaded 0 test images", "logger": "soko_yetu_ai", "module": "image_loader", "function": "get_data_generators", "line": 54}
